Workbook

Sheet MIS
A1: S.NO | B1: Indent Date | C1: Indent | D1: Allocation Date | E1: Customer Name | F1: Location | G1: Vehicle Model | H1: Vehicle Number | I1: Vehicle Based | J1: LR No. | K1: Material | L1: Load Per bucket (Kgs) | M1: No. of Buckets/Barrels | N1: T. Load (Kgs) | O1: POD Received | P1: Loading Charge (Rs.95 per Ton) | Q1: Unloading Charge | R1: Actual Running | S1: Billable Running | T1: Range | U1: Revenue | V1: Total Cost | W1: PnL
A2: 1 | B2: 45733 | C2: S/Drona/03/25/01 | D2: 45734 | E2: Cargo Motors | F2: Delhi | G2: 1109 | H2: HR38AC7854 | I2: Fixed | J2: 0003 | K2: DEF Buckets | L2: 20 | M2: 200 | N2: =L2*M2 -> 4000 | O2: Yes | P2: =(N2/1000)*'Rate Card'!$L$2 -> 380 | Q2: =M2*5 -> 1000 | R2: 321 | S2: =R2/2 -> 160.5 | V2: =R2*'Vehicle Master'!$F$2+MIS!P2+MIS!Q2 -> 11331 | W2: =U2-V2 -> -11331
A3: =A2+1 -> 2 | B3: 45733 | C3: S/Drona/03/25/01 | D3: 45734 | E3: Cargo Motors | F3: Delhi | G3: 1109 | H3: HR38AC7854 | I3: Fixed | J3: 0003 | K3: Barrels | L3: 210 | M3: 3 | N3: =L3*M3 -> 630 | O3: Yes | P3: =(N3/1000)*'Rate Card'!$L$2 -> 59.85 | Q3: 0 | R3: 0 | S3: 0 | V3: =R3*'Vehicle Master'!$F$2+MIS!P3+MIS!Q3 -> 59.85 | W3: =U3-V3 -> -59.85
A4: =A3+1 -> 3 | B4: 45733 | C4: S/Drona/03/25/02 | D4: 45734 | E4: VLH Marketing | F4: Karnal | G4: 1109 | H4: HR38AC7243 | I4: Fixed | J4: 0001 | K4: DEF Buckets | L4: 20 | M4: 300 | N4: =L4*M4 -> 6000 | O4: Yes | P4: =(N4/1000)*'Rate Card'!$L$2 -> 570 | Q4: =M4*5 -> 1500 | R4: 189 | S4: =R4/2 -> 94.5 | V4: =R4*'Vehicle Master'!$F$2+MIS!P4+MIS!Q4 -> 7929 | W4: =U4-V4 -> -7929
A5: =A4+1 -> 4 | B5: 45734 | C5: S/Drona/03/25/03 | D5: 45734 | E5: Johar Automobiles | F5: Faridabad | G5: 1109 | H5: HR38AC0599 | I5: Fixed | J5: 0002 | K5: DEF Buckets | L5: 20 | M5: 300 | N5: =L5*M5 -> 6000 | O5: Yes | P5: =(N5/1000)*'Rate Card'!$L$2 -> 570 | Q5: =M5*5 -> 1500 | R5: 73 | S5: =R5/2 -> 36.5 | V5: =R5*'Vehicle Master'!$F$2+MIS!P5+MIS!Q5 -> 4333 | W5: =U5-V5 -> -4333
A6: =A5+1 -> 5 | B6: 45734 | C6: S/Drona/03/25/04 | D6: 45734 | E6: Pasco Motors LLP | F6: New Delhi | G6: 1109 | H6: HR38AC0263 | I6: Fixed | J6: 0004 | K6: DEF Buckets | L6: 20 | M6: 300 | N6: =L6*M6 -> 6000 | O6: Yes | P6: =(N6/1000)*'Rate Card'!$L$2 -> 570 | Q6: =M6*5 -> 1500 | R6: 139 | S6: =R6/2 -> 69.5 | V6: =R6*'Vehicle Master'!$F$2+MIS!P6+MIS!Q6 -> 6379 | W6: =U6-V6 -> -6379
A7: =A6+1 -> 6 | B7: 45734 | C7: S/Drona/03/25/06 | D7: 45736 | E7: Pasco Motors LLP | F7: New Delhi | G7: 1109 | H7: HR38AC7243 | I7: Fixed | J7: 0009 | K7: DEF Buckets | L7: 20 | M7: 100 | N7: =L7*M7 -> 2000 | P7: =(N7/1000)*'Rate Card'!$L$2 -> 190 | Q7: =M7*5 -> 500 | S7: =R7/2 -> 0 | V7: =R7*'Vehicle Master'!$F$2+MIS!P7+MIS!Q7 -> 690 | W7: =U7-V7 -> -690
A8: =A7+1 -> 7 | B8: 45734 | C8: S/Drona/03/25/07 | D8: 45735 | E8: Yuvraj Motors | F8: Aligarh | G8: 1109 | H8: HR38AC0263 | I8: Fixed | J8: 0006 | K8: DEF Buckets | L8: 20 | M8: 300 | N8: =L8*M8 -> 6000 | O8: Yes | P8: =(N8/1000)*'Rate Card'!$L$2 -> 570 | Q8: =M8*5 -> 1500 | R8: 372 | S8: =R8/2 -> 186 | V8: =R8*'Vehicle Master'!$F$2+MIS!P8+MIS!Q8 -> 13602 | W8: =U8-V8 -> -13602
A9: =A8+1 -> 8 | B9: 45734 | C9: S/Drona/03/25/08 | D9: 45735 | E9: UP State Road Transport Corporation | F9: Gaziabad | G9: 1109 | H9: HR38AC7854 | I9: Fixed | J9: 0005 | K9: DEF Barrels | L9: 210 | M9: 30 | N9: =L9*M9 -> 6300 | O9: Yes | P9: =(N9/1000)*'Rate Card'!$L$2 -> 598.5 | Q9: =M9*30 -> 900 | R9: 183 | S9: =R9/2 -> 91.5 | V9: =R9*'Vehicle Master'!$F$2+MIS!P9+MIS!Q9 -> 7171.5 | W9: =U9-V9 -> -7171.5
A10: =A9+1 -> 9 | B10: 45734 | C10: S/Drona/03/25/09 | D10: 45735 | E10: UP State Road Transport Corporation | F10: Gaziabad | G10: 1109 | H10: HR38AC7243 | I10: Fixed | J10: 0007 | K10: DEF Barrels | L10: 210 | M10: 30 | N10: =L10*M10 -> 6300 | O10: No | P10: =(N10/1000)*'Rate Card'!$L$2 -> 598.5 | Q10: =M10*30 -> 900 | R10: 166 | S10: =R10/2 -> 83 | V10: =R10*'Vehicle Master'!$F$2+MIS!P10+MIS!Q10 -> 6644.5 | W10: =U10-V10 -> -6644.5
A11: =A10+1 -> 10 | B11: 45735 | C11: S/Drona/03/25/10 | D11: 45736 | E11: Sisothiya Automobile | F11: Dharuhera | G11: 1109 | H11: HR38AC0599 | I11: Fixed | J11: 0008 | K11: DEF Buckets | L11: 20 | M11: 100 | N11: =L11*M11 -> 2000 | O11: Yes | P11: =(N11/1000)*'Rate Card'!$L$2 -> 190 | Q11: =M11*5 -> 500 | R11: 243 | S11: =R11/2 -> 121.5 | V11: =R11*'Vehicle Master'!$F$2+MIS!P11+MIS!Q11 -> 8223 | W11: =U11-V11 -> -8223
A12: =A11+1 -> 11 | B12: 45735 | C12: S/Drona/03/25/11 | D12: 45736 | E12: Sahni Motors | F12: Karnal | G12: 1109 | H12: HR38AC7854 | I12: Fixed | J12: 0010 | K12: DEF Buckets | L12: 20 | M12: 200 | N12: =L12*M12 -> 4000 | O12: No | P12: =(N12/1000)*'Rate Card'!$L$2 -> 380 | Q12: =M12*5 -> 1000 | R12: 177 | S12: =R12/2 -> 88.5 | V12: =R12*'Vehicle Master'!$F$2+MIS!P12+MIS!Q12 -> 6867 | W12: =U12-V12 -> -6867
A13: =A12+1 -> 12 | B13: 45735 | C13: S/Drona/03/25/11 | D13: 45736 | E13: Sahni Motors | F13: Karnal | G13: 1109 | H13: HR38AC7854 | I13: Fixed | J13: 0010 | K13: Jerry Can | L13: 20 | M13: 100 | N13: =L13*M13 -> 2000 | O13: No | P13: =(N13/1000)*'Rate Card'!$L$2 -> 190 | Q13: =M13*5 -> 500 | R13: 0 | S13: =R13/2 -> 0 | V13: =R13*'Vehicle Master'!$F$2+MIS!P13+MIS!Q13 -> 690 | W13: =U13-V13 -> -690

Sheet OPs Data
A1: S.NO | B1: Indent Date | C1: Indent | D1: Allocation Date | E1: Customer Name | F1: Range | G1: Location | H1: Vehicle Number | I1: Vehicle Model | J1: Vehicle Based | K1: LR No. | L1: Material | M1: Load Per bucket (Kgs) | N1: No. of Buckets/Barrels | O1: T. Load (Kgs) | P1: POD Received | Q1: FREIGHT Tiger Number | R1: Freight Tiger Month | S1: REMARKS | U1: Total Km ( TpT) | V1: Rate | W1: Total Cost | X1: =SUBTOTAL(9,W:W) -> 4182101 | Y1: Total Cost(Loading) | Z1: =SUBTOTAL(9,Y:Y) -> 288943.45 | AA1: Criteria | AB1: Total cost Unload | AC1: =SUBTOTAL(9,AB:AB) -> 707255 | AD1: Any Other Cost | AE1: Total Cost | AF1: =SUBTOTAL(9,AE:AE) -> 5209799.4 | AG1: Criteria | AH1: Cost | AI1: Revenue | AJ1: =SUBTOTAL(9,AI:AI) -> 5011717 | AK1: P & L | AL1: =SUBTOTAL(9,AK:AK) -> -198082.45 | AN1: Km/2
A2: 1 | B2: 45733 | C2: S/Drona/03/25/01 | D2: 45734 | E2: Cargo Motors | F2: 0-100Km | G2: Delhi | H2: HR38AC7854 | I2: 1109 | J2: Fixed | K2: 3 | L2: 20L Buckets | M2: =IFERROR(VLOOKUP(L2,'Material Master'!B:C,2,0),"") -> 20 | N2: 200 | O2: =IFERROR(M2*N2,"") -> 4000 | P2: Yes | R2: 45717 | U2: 73 | V2: 31 | W2: =IFERROR(U2*V2,"0") -> 2263 | Y2: =IFERROR((O2/1000)*Masters!$C$3,"0") -> 380 | AA2: =IFERROR(VLOOKUP(L2,Masters!G:H,2,0),"0") -> 5 | AB2: =IFERROR(AA2*N2,"0") -> 1000 | AE2: =W2+Y2+AB2+AD2 -> 3643 | AG2: =M2&"-"&F2 -> 20-0-100Km | AH2: =IFERROR(VLOOKUP(AG2,Masters!N:O,2,0),"0") -> 21 | AI2: =AH2*N2 -> 4200 | AK2: =AI2-AE2 -> 557 | AN2: =IFERROR(U2/2,"0") -> 36.5
A3: =A2+1 -> 2 | B3: 45733 | C3: S/Drona/03/25/01 | D3: 45734 | E3: Cargo Motors | F3: 0-100Km | G3: Delhi | H3: HR38AC7854 | I3: 1109 | J3: Fixed | K3: 3 | L3: 210L Barrels | M3: =IFERROR(VLOOKUP(L3,'Material Master'!B:C,2,0),"") -> 210 | N3: 3 | O3: =IFERROR(M3*N3,"") -> 630 | P3: Yes | R3: 45717 | U3: 0 | V3: 31 | W3: =IFERROR(U3*V3,"0") -> 0 | Y3: =IFERROR((O3/1000)*Masters!$C$3,"0") -> 59.85 | AA3: =IFERROR(VLOOKUP(L3,Masters!G:H,2,0),"0") -> 30 | AB3: =IFERROR(AA3*N3,"0") -> 90 | AE3: =W3+Y3+AB3+AD3 -> 149.85 | AG3: =M3&"-"&F3 -> 210-0-100Km | AH3: =IFERROR(VLOOKUP(AG3,Masters!N:O,2,0),"0") -> 220.5 | AI3: =AH3*N3 -> 661.5 | AK3: =AI3-AE3 -> 511.65 | AN3: =IFERROR(U3/2,"0") -> 0
A4: =A3+1 -> 3 | B4: 45733 | C4: S/Drona/03/25/02 | D4: 45734 | E4: VLH Marketing | F4: 0-100Km | G4: Karnal | H4: HR38AC7243 | I4: 1109 | J4: Fixed | K4: 1 | L4: 20L Buckets | M4: =IFERROR(VLOOKUP(L4,'Material Master'!B:C,2,0),"") -> 20 | N4: 300 | O4: =IFERROR(M4*N4,"") -> 6000 | P4: Yes | R4: 45717 | U4: 189 | V4: 31 | W4: =IFERROR(U4*V4,"0") -> 5859 | Y4: =IFERROR((O4/1000)*Masters!$C$3,"0") -> 570 | AA4: =IFERROR(VLOOKUP(L4,Masters!G:H,2,0),"0") -> 5 | AB4: =IFERROR(AA4*N4,"0") -> 1500 | AE4: =W4+Y4+AB4+AD4 -> 7929 | AG4: =M4&"-"&F4 -> 20-0-100Km | AH4: =IFERROR(VLOOKUP(AG4,Masters!N:O,2,0),"0") -> 21 | AI4: =AH4*N4 -> 6300 | AK4: =AI4-AE4 -> -1629 | AN4: =IFERROR(U4/2,"0") -> 94.5
A5: =A4+1 -> 4 | B5: 45734 | C5: S/Drona/03/25/03 | D5: 45734 | E5: Johar Automobiles | F5: 101-250Km | G5: Faridabad | H5: HR38AC0599 | I5: 1109 | J5: Fixed | K5: 2 | L5: 20L Buckets | M5: =IFERROR(VLOOKUP(L5,'Material Master'!B:C,2,0),"") -> 20 | N5: 300 | O5: =IFERROR(M5*N5,"") -> 6000 | P5: Yes | R5: 45717 | U5: 321 | V5: 31 | W5: =IFERROR(U5*V5,"0") -> 9951 | Y5: =IFERROR((O5/1000)*Masters!$C$3,"0") -> 570 | AA5: =IFERROR(VLOOKUP(L5,Masters!G:H,2,0),"0") -> 5 | AB5: =IFERROR(AA5*N5,"0") -> 1500 | AE5: =W5+Y5+AB5+AD5 -> 12021 | AG5: =M5&"-"&F5 -> 20-101-250Km | AH5: =IFERROR(VLOOKUP(AG5,Masters!N:O,2,0),"0") -> 40 | AI5: =AH5*N5 -> 12000 | AK5: =AI5-AE5 -> -21 | AN5: =IFERROR(U5/2,"0") -> 160.5
A6: =A5+1 -> 5 | B6: 45734 | C6: S/Drona/03/25/04 | D6: 45734 | E6: Pasco Motors LLP | F6: 0-100Km | G6: New Delhi | H6: HR38AC0263 | I6: 1109 | J6: Fixed | K6: 4 | L6: 20L Buckets | M6: =IFERROR(VLOOKUP(L6,'Material Master'!B:C,2,0),"") -> 20 | N6: 300 | O6: =IFERROR(M6*N6,"") -> 6000 | P6: Yes | R6: 45717 | U6: 139 | V6: 31 | W6: =IFERROR(U6*V6,"0") -> 4309 | Y6: =IFERROR((O6/1000)*Masters!$C$3,"0") -> 570 | AA6: =IFERROR(VLOOKUP(L6,Masters!G:H,2,0),"0") -> 5 | AB6: =IFERROR(AA6*N6,"0") -> 1500 | AE6: =W6+Y6+AB6+AD6 -> 6379 | AG6: =M6&"-"&F6 -> 20-0-100Km | AH6: =IFERROR(VLOOKUP(AG6,Masters!N:O,2,0),"0") -> 21 | AI6: =AH6*N6 -> 6300 | AK6: =AI6-AE6 -> -79 | AN6: =IFERROR(U6/2,"0") -> 69.5
A7: =A6+1 -> 6 | B7: 45734 | C7: S/Drona/03/25/06 | D7: 45736 | E7: Pasco Motors LLP | F7: 0-100Km | G7: New Delhi | H7: HR38AC7243 | I7: 1109 | J7: Fixed | K7: 9 | L7: 20L Buckets | M7: =IFERROR(VLOOKUP(L7,'Material Master'!B:C,2,0),"") -> 20 | N7: 100 | O7: =IFERROR(M7*N7,"") -> 2000 | P7: Yes | R7: 45717 | U7: 146 | V7: 31 | W7: =IFERROR(U7*V7,"0") -> 4526 | Y7: =IFERROR((O7/1000)*Masters!$C$3,"0") -> 190 | AA7: =IFERROR(VLOOKUP(L7,Masters!G:H,2,0),"0") -> 5 | AB7: =IFERROR(AA7*N7,"0") -> 500 | AE7: =W7+Y7+AB7+AD7 -> 5216 | AG7: =M7&"-"&F7 -> 20-0-100Km | AH7: =IFERROR(VLOOKUP(AG7,Masters!N:O,2,0),"0") -> 21 | AI7: =AH7*N7 -> 2100 | AK7: =AI7-AE7 -> -3116 | AN7: =IFERROR(U7/2,"0") -> 73
A8: =A7+1 -> 7 | B8: 45734 | C8: S/Drona/03/25/07 | D8: 45735 | E8: Yuvraj Motors | F8: 101-250Km | G8: Aligarh | H8: HR38AC0263 | I8: 1109 | J8: Fixed | K8: 6 | L8: 20L Buckets | M8: =IFERROR(VLOOKUP(L8,'Material Master'!B:C,2,0),"") -> 20 | N8: 300 | O8: =IFERROR(M8*N8,"") -> 6000 | P8: Yes | R8: 45717 | U8: 372 | V8: 31 | W8: =IFERROR(U8*V8,"0") -> 11532 | Y8: =IFERROR((O8/1000)*Masters!$C$3,"0") -> 570 | AA8: =IFERROR(VLOOKUP(L8,Masters!G:H,2,0),"0") -> 5 | AB8: =IFERROR(AA8*N8,"0") -> 1500 | AE8: =W8+Y8+AB8+AD8 -> 13602 | AG8: =M8&"-"&F8 -> 20-101-250Km | AH8: =IFERROR(VLOOKUP(AG8,Masters!N:O,2,0),"0") -> 40 | AI8: =AH8*N8 -> 12000 | AK8: =AI8-AE8 -> -1602 | AN8: =IFERROR(U8/2,"0") -> 186
A9: =A8+1 -> 8 | B9: 45734 | C9: S/Drona/03/25/08 | D9: 45735 | E9: UP State Road Transport Corporation | F9: 0-100Km | G9: Gaziabad | H9: HR38AC7854 | I9: 1109 | J9: Fixed | K9: 5 | L9: 210L Barrels | M9: =IFERROR(VLOOKUP(L9,'Material Master'!B:C,2,0),"") -> 210 | N9: 30 | O9: =IFERROR(M9*N9,"") -> 6300 | P9: Yes | R9: 45717 | U9: 183 | V9: 31 | W9: =IFERROR(U9*V9,"0") -> 5673 | Y9: =IFERROR((O9/1000)*Masters!$C$3,"0") -> 598.5 | AA9: =IFERROR(VLOOKUP(L9,Masters!G:H,2,0),"0") -> 30 | AB9: =IFERROR(AA9*N9,"0") -> 900 | AE9: =W9+Y9+AB9+AD9 -> 7171.5 | AG9: =M9&"-"&F9 -> 210-0-100Km | AH9: =IFERROR(VLOOKUP(AG9,Masters!N:O,2,0),"0") -> 220.5 | AI9: =AH9*N9 -> 6615 | AK9: =AI9-AE9 -> -556.5 | AN9: =IFERROR(U9/2,"0") -> 91.5
A10: =A9+1 -> 9 | B10: 45734 | C10: S/Drona/03/25/09 | D10: 45735 | E10: UP State Road Transport Corporation | F10: 0-100Km | G10: Gaziabad | H10: HR38AC7243 | I10: 1109 | J10: Fixed | K10: 7 | L10: 210L Barrels | M10: =IFERROR(VLOOKUP(L10,'Material Master'!B:C,2,0),"") -> 210 | N10: 30 | O10: =IFERROR(M10*N10,"") -> 6300 | P10: Yes | R10: 45717 | U10: 166 | V10: 31 | W10: =IFERROR(U10*V10,"0") -> 5146 | Y10: =IFERROR((O10/1000)*Masters!$C$3,"0") -> 598.5 | AA10: =IFERROR(VLOOKUP(L10,Masters!G:H,2,0),"0") -> 30 | AB10: =IFERROR(AA10*N10,"0") -> 900 | AE10: =W10+Y10+AB10+AD10 -> 6644.5 | AG10: =M10&"-"&F10 -> 210-0-100Km | AH10: =IFERROR(VLOOKUP(AG10,Masters!N:O,2,0),"0") -> 220.5 | AI10: =AH10*N10 -> 6615 | AK10: =AI10-AE10 -> -29.5 | AN10: =IFERROR(U10/2,"0") -> 83
A11: =A10+1 -> 10 | B11: 45735 | C11: S/Drona/03/25/10 | D11: 45736 | E11: Sisothiya Automobile | F11: 101-250Km | G11: Dharuhera | H11: HR38AC0599 | I11: 1109 | J11: Fixed | K11: 8 | L11: 20L Buckets | M11: =IFERROR(VLOOKUP(L11,'Material Master'!B:C,2,0),"") -> 20 | N11: 100 | O11: =IFERROR(M11*N11,"") -> 2000 | P11: Yes | R11: 45717 | U11: 243 | V11: 31 | W11: =IFERROR(U11*V11,"0") -> 7533 | Y11: =IFERROR((O11/1000)*Masters!$C$3,"0") -> 190 | AA11: =IFERROR(VLOOKUP(L11,Masters!G:H,2,0),"0") -> 5 | AB11: =IFERROR(AA11*N11,"0") -> 500 | AE11: =W11+Y11+AB11+AD11 -> 8223 | AG11: =M11&"-"&F11 -> 20-101-250Km | AH11: =IFERROR(VLOOKUP(AG11,Masters!N:O,2,0),"0") -> 40 | AI11: =AH11*N11 -> 4000 | AK11: =AI11-AE11 -> -4223 | AN11: =IFERROR(U11/2,"0") -> 121.5
A12: =A11+1 -> 11 | B12: 45735 | C12: S/Drona/03/25/11 | D12: 45736 | E12: Sahni Motors | F12: 0-100Km | G12: Karnal | H12: HR38AC7854 | I12: 1109 | J12: Fixed | K12: 10 | L12: 20L Buckets | M12: =IFERROR(VLOOKUP(L12,'Material Master'!B:C,2,0),"") -> 20 | N12: 200 | O12: =IFERROR(M12*N12,"") -> 4000 | P12: Yes | R12: 45717 | U12: 177 | V12: 31 | W12: =IFERROR(U12*V12,"0") -> 5487 | Y12: =IFERROR((O12/1000)*Masters!$C$3,"0") -> 380 | AA12: =IFERROR(VLOOKUP(L12,Masters!G:H,2,0),"0") -> 5 | AB12: =IFERROR(AA12*N12,"0") -> 1000 | AE12: =W12+Y12+AB12+AD12 -> 6867 | AG12: =M12&"-"&F12 -> 20-0-100Km | AH12: =IFERROR(VLOOKUP(AG12,Masters!N:O,2,0),"0") -> 21 | AI12: =AH12*N12 -> 4200 | AK12: =AI12-AE12 -> -2667 | AN12: =IFERROR(U12/2,"0") -> 88.5
A13: =A12+1 -> 12 | B13: 45735 | C13: S/Drona/03/25/11 | D13: 45736 | E13: Sahni Motors | F13: 0-100Km | G13: Karnal | H13: HR38AC7854 | I13: 1109 | J13: Fixed | K13: 10 | L13: 20L Buckets | M13: =IFERROR(VLOOKUP(L13,'Material Master'!B:C,2,0),"") -> 20 | N13: 100 | O13: =IFERROR(M13*N13,"") -> 2000 | P13: Yes | R13: 45717 | S13: DOUBLE CHALLAN | U13: 0 | V13: 31 | W13: =IFERROR(U13*V13,"0") -> 0 | Y13: =IFERROR((O13/1000)*Masters!$C$3,"0") -> 190 | AA13: =IFERROR(VLOOKUP(L13,Masters!G:H,2,0),"0") -> 5 | AB13: =IFERROR(AA13*N13,"0") -> 500 | AE13: =W13+Y13+AB13+AD13 -> 690 | AG13: =M13&"-"&F13 -> 20-0-100Km | AH13: =IFERROR(VLOOKUP(AG13,Masters!N:O,2,0),"0") -> 21 | AI13: =AH13*N13 -> 2100 | AK13: =AI13-AE13 -> 1410 | AN13: =IFERROR(U13/2,"0") -> 0
A14: =A13+1 -> 13 | B14: 45737 | C14: S/Drona/03/25/12 | D14: 45737 | E14: AA Automobiles Pvt. Ltd. | F14: 0-100Km | G14: Karnal | H14: HR38AC0599 | I14: 1109 | J14: Fixed | K14: 11 | L14: 20L Buckets | M14: =IFERROR(VLOOKUP(L14,'Material Master'!B:C,2,0),"") -> 20 | N14: 300 | O14: =IFERROR(M14*N14,"") -> 6000 | P14: Yes | R14: 45717 | U14: 132 | V14: 31 | W14: =IFERROR(U14*V14,"0") -> 4092 | Y14: =IFERROR((O14/1000)*Masters!$C$3,"0") -> 570 | AA14: =IFERROR(VLOOKUP(L14,Masters!G:H,2,0),"0") -> 5 | AB14: =IFERROR(AA14*N14,"0") -> 1500 | AE14: =W14+Y14+AB14+AD14 -> 6162 | AG14: =M14&"-"&F14 -> 20-0-100Km | AH14: =IFERROR(VLOOKUP(AG14,Masters!N:O,2,0),"0") -> 21 | AI14: =AH14*N14 -> 6300 | AK14: =AI14-AE14 -> 138 | AN14: =IFERROR(U14/2,"0") -> 66
A15: =A14+1 -> 14 | B15: 45737 | C15: S/Drona/03/25/13 | D15: 45737 | E15: Jain Motors Srore | F15: 101-250Km | G15: Tohana | H15: HR38AC0263 | I15: 1109 | J15: Fixed | K15: 12 | L15: 20L Buckets | M15: =IFERROR(VLOOKUP(L15,'Material Master'!B:C,2,0),"") -> 20 | N15: 300 | O15: =IFERROR(M15*N15,"") -> 6000 | P15: Yes | R15: 45717 | U15: 371 | V15: 31 | W15: =IFERROR(U15*V15,"0") -> 11501 | Y15: =IFERROR((O15/1000)*Masters!$C$3,"0") -> 570 | AA15: =IFERROR(VLOOKUP(L15,Masters!G:H,2,0),"0") -> 5 | AB15: =IFERROR(AA15*N15,"0") -> 1500 | AE15: =W15+Y15+AB15+AD15 -> 13571 | AG15: =M15&"-"&F15 -> 20-101-250Km | AH15: =IFERROR(VLOOKUP(AG15,Masters!N:O,2,0),"0") -> 40 | AI15: =AH15*N15 -> 12000 | AK15: =AI15-AE15 -> -1571 | AN15: =IFERROR(U15/2,"0") -> 185.5
A16: =A15+1 -> 15 | B16: 45737 | C16: S/Drona/03/25/14 | D16: 45737 | E16: Shree Shyam Automobiles | F16: 251-400Km | G16: Ferozpur | H16: HR38AC7854 | I16: 1109 | J16: Fixed | K16: 13 | L16: 20L Buckets | M16: =IFERROR(VLOOKUP(L16,'Material Master'!B:C,2,0),"") -> 20 | N16: 300 | O16: =IFERROR(M16*N16,"") -> 6000 | P16: Yes | R16: 45717 | U16: 502 | V16: 31 | W16: =IFERROR(U16*V16,"0") -> 15562 | Y16: =IFERROR((O16/1000)*Masters!$C$3,"0") -> 570 | AA16: =IFERROR(VLOOKUP(L16,Masters!G:H,2,0),"0") -> 5 | AB16: =IFERROR(AA16*N16,"0") -> 1500 | AE16: =W16+Y16+AB16+AD16 -> 17632 | AG16: =M16&"-"&F16 -> 20-251-400Km | AH16: =IFERROR(VLOOKUP(AG16,Masters!N:O,2,0),"0") -> 68 | AI16: =AH16*N16 -> 20400 | AK16: =AI16-AE16 -> 2768 | AN16: =IFERROR(U16/2,"0") -> 251
A17: =A16+1 -> 16 | B17: 45737 | C17: S/Drona/03/25/15 | D17: 45737 | E17: RK Automobiles Private Limited | F17: 0-100Km | G17: Sahibabad | H17: HR38AC7243 | I17: 1109 | J17: Fixed | K17: 14 | L17: 210L Barrels | M17: =IFERROR(VLOOKUP(L17,'Material Master'!B:C,2,0),"") -> 210 | N17: 30 | O17: =IFERROR(M17*N17,"") -> 6300 | P17: Yes | R17: 45717 | U17: 159 | V17: 31 | W17: =IFERROR(U17*V17,"0") -> 4929 | Y17: =IFERROR((O17/1000)*Masters!$C$3,"0") -> 598.5 | AA17: =IFERROR(VLOOKUP(L17,Masters!G:H,2,0),"0") -> 30 | AB17: =IFERROR(AA17*N17,"0") -> 900 | AE17: =W17+Y17+AB17+AD17 -> 6427.5 | AG17: =M17&"-"&F17 -> 210-0-100Km | AH17: =IFERROR(VLOOKUP(AG17,Masters!N:O,2,0),"0") -> 220.5 | AI17: =AH17*N17 -> 6615 | AK17: =AI17-AE17 -> 187.5 | AN17: =IFERROR(U17/2,"0") -> 79.5
A18: =A17+1 -> 17 | B18: 45738 | C18: S/Drona/03/25/16 | D18: 45738 | E18: Metro Motors Pvt Ltd. | F18: 0-100Km | G18: Karnal | H18: HR38AC0263 | I18: 909 | J18: Fixed | K18: 15 | L18: 20L Buckets | M18: =IFERROR(VLOOKUP(L18,'Material Master'!B:C,2,0),"") -> 20 | N18: 200 | O18: =IFERROR(M18*N18,"") -> 4000 | P18: Yes | R18: 45717 | U18: 200 | V18: 31 | W18: =IFERROR(U18*V18,"0") -> 6200 | Y18: =IFERROR((O18/1000)*Masters!$C$3,"0") -> 380 | AA18: =IFERROR(VLOOKUP(L18,Masters!G:H,2,0),"0") -> 5 | AB18: =IFERROR(AA18*N18,"0") -> 1000 | AE18: =W18+Y18+AB18+AD18 -> 7580 | AG18: =M18&"-"&F18 -> 20-0-100Km | AH18: =IFERROR(VLOOKUP(AG18,Masters!N:O,2,0),"0") -> 21 | AI18: =AH18*N18 -> 4200 | AK18: =AI18-AE18 -> -3380 | AN18: =IFERROR(U18/2,"0") -> 100
A19: =A18+1 -> 18 | B19: 45738 | C19: S/Drona/03/25/17 | D19: 45738 | E19: Pasco Motors LLP | F19: 0-100Km | G19: New Delhi | H19: HR38AC0599 | I19: 1109 | J19: Fixed | K19: 16 | L19: 20L Buckets | M19: =IFERROR(VLOOKUP(L19,'Material Master'!B:C,2,0),"") -> 20 | N19: 300 | O19: =IFERROR(M19*N19,"") -> 6000 | P19: Yes | R19: 45717 | U19: 171 | V19: 31 | W19: =IFERROR(U19*V19,"0") -> 5301 | Y19: =IFERROR((O19/1000)*Masters!$C$3,"0") -> 570 | AA19: =IFERROR(VLOOKUP(L19,Masters!G:H,2,0),"0") -> 5 | AB19: =IFERROR(AA19*N19,"0") -> 1500 | AE19: =W19+Y19+AB19+AD19 -> 7371 | AG19: =M19&"-"&F19 -> 20-0-100Km | AH19: =IFERROR(VLOOKUP(AG19,Masters!N:O,2,0),"0") -> 21 | AI19: =AH19*N19 -> 6300 | AK19: =AI19-AE19 -> -1071 | AN19: =IFERROR(U19/2,"0") -> 85.5
A20: =A19+1 -> 19 | B20: 45740 | C20: S/Drona/03/25/18 | D20: 45740 | E20: Sahni Motors | F20: 0-100Km | G20: Karnal | H20: HR38AC7243 | I20: 1109 | J20: Fixed | K20: 17 | L20: 20L Buckets | M20: =IFERROR(VLOOKUP(L20,'Material Master'!B:C,2,0),"") -> 20 | N20: 300 | O20: =IFERROR(M20*N20,"") -> 6000 | P20: Yes | R20: 45717 | U20: 179 | V20: 31 | W20: =IFERROR(U20*V20,"0") -> 5549 | Y20: =IFERROR((O20/1000)*Masters!$C$3,"0") -> 570 | AA20: =IFERROR(VLOOKUP(L20,Masters!G:H,2,0),"0") -> 5 | AB20: =IFERROR(AA20*N20,"0") -> 1500 | AE20: =W20+Y20+AB20+AD20 -> 7619 | AG20: =M20&"-"&F20 -> 20-0-100Km | AH20: =IFERROR(VLOOKUP(AG20,Masters!N:O,2,0),"0") -> 21 | AI20: =AH20*N20 -> 6300 | AK20: =AI20-AE20 -> -1319 | AN20: =IFERROR(U20/2,"0") -> 89.5
A21: =A20+1 -> 20 | B21: 45740 | C21: S/Drona/03/25/19 | D21: 45740 | E21: mangalam auto | F21: 101-250Km | G21: Palwal | H21: HR38AC0263 | I21: 1109 | J21: Fixed | K21: 18 | L21: 20L Buckets | M21: =IFERROR(VLOOKUP(L21,'Material Master'!B:C,2,0),"") -> 20 | N21: 300 | O21: =IFERROR(M21*N21,"") -> 6000 | P21: Yes | R21: 45717 | U21: 320 | V21: 31 | W21: =IFERROR(U21*V21,"0") -> 9920 | Y21: =IFERROR((O21/1000)*Masters!$C$3,"0") -> 570 | AA21: =IFERROR(VLOOKUP(L21,Masters!G:H,2,0),"0") -> 5 | AB21: =IFERROR(AA21*N21,"0") -> 1500 | AE21: =W21+Y21+AB21+AD21 -> 11990 | AG21: =M21&"-"&F21 -> 20-101-250Km | AH21: =IFERROR(VLOOKUP(AG21,Masters!N:O,2,0),"0") -> 40 | AI21: =AH21*N21 -> 12000 | AK21: =AI21-AE21 -> 10 | AN21: =IFERROR(U21/2,"0") -> 160
A22: =A21+1 -> 21 | B22: 45740 | C22: S/Drona/03/25/20 | D22: 45740 | E22: UP State Road Transport Corporation | F22: 101-250Km | G22: Saharanpur | H22: HR38AC0599 | I22: 1109 | J22: Fixed | K22: 19 | L22: 210L Barrels | M22: =IFERROR(VLOOKUP(L22,'Material Master'!B:C,2,0),"") -> 210 | N22: 30 | O22: =IFERROR(M22*N22,"") -> 6300 | P22: Yes | R22: 45717 | U22: 388 | V22: 31 | W22: =IFERROR(U22*V22,"0") -> 12028 | Y22: =IFERROR((O22/1000)*Masters!$C$3,"0") -> 598.5 | AA22: =IFERROR(VLOOKUP(L22,Masters!G:H,2,0),"0") -> 30 | AB22: =IFERROR(AA22*N22,"0") -> 900 | AE22: =W22+Y22+AB22+AD22 -> 13526.5 | AG22: =M22&"-"&F22 -> 210-101-250Km | AH22: =IFERROR(VLOOKUP(AG22,Masters!N:O,2,0),"0") -> 420 | AI22: =AH22*N22 -> 12600 | AK22: =AI22-AE22 -> -926.5 | AN22: =IFERROR(U22/2,"0") -> 194
A23: =A22+1 -> 22 | B23: 45741 | C23: S/Drona/03/25/22 | D23: 45741 | E23: Raj Enterprize | F23: 101-250Km | G23: Greater Noida | H23: HR38AC7854 | I23: 1109 | J23: Fixed | K23: 20 | L23: 20L Buckets | M23: =IFERROR(VLOOKUP(L23,'Material Master'!B:C,2,0),"") -> 20 | N23: 100 | O23: =IFERROR(M23*N23,"") -> 2000 | P23: Yes | R23: 45717 | U23: 224 | V23: 31 | W23: =IFERROR(U23*V23,"0") -> 6944 | Y23: =IFERROR((O23/1000)*Masters!$C$3,"0") -> 190 | AA23: =IFERROR(VLOOKUP(L23,Masters!G:H,2,0),"0") -> 5 | AB23: =IFERROR(AA23*N23,"0") -> 500 | AE23: =W23+Y23+AB23+AD23 -> 7634 | AG23: =M23&"-"&F23 -> 20-101-250Km | AH23: =IFERROR(VLOOKUP(AG23,Masters!N:O,2,0),"0") -> 40 | AI23: =AH23*N23 -> 4000 | AK23: =AI23-AE23 -> -3634 | AN23: =IFERROR(U23/2,"0") -> 112
A24: =A23+1 -> 23 | B24: 45741 | C24: S/Drona/03/25/22 | D24: 45741 | E24: Ashok Ventures LLP | F24: 101-250Km | G24: Gautam Buddha Nagar | H24: HR38AC7854 | I24: 1109 | J24: Fixed | K24: 21 | L24: 20L Buckets | M24: =IFERROR(VLOOKUP(L24,'Material Master'!B:C,2,0),"") -> 20 | N24: 100 | O24: =IFERROR(M24*N24,"") -> 2000 | P24: Yes | R24: 45717 | U24: 0 | V24: 31 | W24: =IFERROR(U24*V24,"0") -> 0 | Y24: =IFERROR((O24/1000)*Masters!$C$3,"0") -> 190 | AA24: =IFERROR(VLOOKUP(L24,Masters!G:H,2,0),"0") -> 5 | AB24: =IFERROR(AA24*N24,"0") -> 500 | AE24: =W24+Y24+AB24+AD24 -> 690 | AG24: =M24&"-"&F24 -> 20-101-250Km | AH24: =IFERROR(VLOOKUP(AG24,Masters!N:O,2,0),"0") -> 40 | AI24: =AH24*N24 -> 4000 | AK24: =AI24-AE24 -> 3310 | AN24: =IFERROR(U24/2,"0") -> 0
A25: =A24+1 -> 24 | B25: 45741 | C25: S/Drona/03/25/23 | D25: 45741 | E25: Pasco Motors LLP | F25: 0-100Km | G25: New Delhi | H25: HR38AC7243 | I25: 1109 | J25: Fixed | K25: 22 | L25: 20L Buckets | M25: =IFERROR(VLOOKUP(L25,'Material Master'!B:C,2,0),"") -> 20 | N25: 300 | O25: =IFERROR(M25*N25,"") -> 6000 | P25: Yes | R25: 45717 | U25: 143 | V25: 31 | W25: =IFERROR(U25*V25,"0") -> 4433 | Y25: =IFERROR((O25/1000)*Masters!$C$3,"0") -> 570 | AA25: =IFERROR(VLOOKUP(L25,Masters!G:H,2,0),"0") -> 5 | AB25: =IFERROR(AA25*N25,"0") -> 1500 | AE25: =W25+Y25+AB25+AD25 -> 6503 | AG25: =M25&"-"&F25 -> 20-0-100Km | AH25: =IFERROR(VLOOKUP(AG25,Masters!N:O,2,0),"0") -> 21 | AI25: =AH25*N25 -> 6300 | AK25: =AI25-AE25 -> -203 | AN25: =IFERROR(U25/2,"0") -> 71.5
... A29: =A28+1 -> 28 | B29: 45742 | C29: s/Drona/03/25/30 | D29: 45742 | E29: Anand motors | F29: 0-100Km | G29: gohana | H29: HR38AC7243 | I29: 1109 | J29: Fixed | K29: 26 | L29: 20L Buckets | M29: =IFERROR(VLOOKUP(L29,'Material Master'!B:C,2,0),"") -> 20 | N29: 300 | O29: =IFERROR(M29*N29,"") -> 6000 | P29: Yes | R29: 45717 | U29: 172 | V29: 31 | W29: =IFERROR(U29*V29,"0") -> 5332 | Y29: =IFERROR((O29/1000)*Masters!$C$3,"0") -> 570 | AA29: =IFERROR(VLOOKUP(L29,Masters!G:H,2,0),"0") -> 5 | AB29: =IFERROR(AA29*N29,"0") -> 1500 | AE29: =W29+Y29+AB29+AD29 -> 7402 | AG29: =M29&"-"&F29 -> 20-0-100Km | AH29: =IFERROR(VLOOKUP(AG29,Masters!N:O,2,0),"0") -> 21 | AI29: =AH29*N29 -> 6300 | AK29: =AI29-AE29 -> -1102 | AN29: =IFERROR(U29/2,"0") -> 86
A30: =A29+1 -> 29 | B30: 45742 | C30: s/Drona/03/25/27 | D30: 45742 | E30: Sanghi Automobiles | F30: 101-250Km | G30: Rewari | H30: HR69D3754 | I30: 709 | J30: Market | K30: 24 | L30: 20L Buckets | M30: =IFERROR(VLOOKUP(L30,'Material Master'!B:C,2,0),"") -> 20 | N30: 100 | O30: =IFERROR(M30*N30,"") -> 2000 | P30: Yes | R30: 45717 | S30: Market | U30: 0 | V30: 31 | W30: 4500 | Y30: =IFERROR((O30/1000)*Masters!$C$3,"0") -> 190 | AA30: =IFERROR(VLOOKUP(L30,Masters!G:H,2,0),"0") -> 5 | AB30: =IFERROR(AA30*N30,"0") -> 500 | AE30: =W30+Y30+AB30+AD30 -> 5190 | AG30: =M30&"-"&F30 -> 20-101-250Km | AH30: =IFERROR(VLOOKUP(AG30,Masters!N:O,2,0),"0") -> 40 | AI30: =AH30*N30 -> 4000 | AK30: =AI30-AE30 -> -1190 | AN30: =IFERROR(U30/2,"0") -> 0
A31: =A30+1 -> 30 | B31: 45742 | C31: s/Drona/03/25/28 | D31: 45742 | E31: Hind Motor | F31: 101-250Km | G31: Hisar | H31: HR39F5155 | I31: 1109 | J31: Market | K31: 25 | L31: 20L Buckets | M31: =IFERROR(VLOOKUP(L31,'Material Master'!B:C,2,0),"") -> 20 | N31: 300 | O31: =IFERROR(M31*N31,"") -> 6000 | P31: Yes | R31: 45717 | S31: Market | U31: 0 | V31: 31 | W31: 8500 | Y31: =IFERROR((O31/1000)*Masters!$C$3,"0") -> 570 | AA31: =IFERROR(VLOOKUP(L31,Masters!G:H,2,0),"0") -> 5 | AB31: =IFERROR(AA31*N31,"0") -> 1500 | AE31: =W31+Y31+AB31+AD31 -> 10570 | AG31: =M31&"-"&F31 -> 20-101-250Km | AH31: =IFERROR(VLOOKUP(AG31,Masters!N:O,2,0),"0") -> 40 | AI31: =AH31*N31 -> 12000 | AK31: =AI31-AE31 -> 1430 | AN31: =IFERROR(U31/2,"0") -> 0
A32: =A31+1 -> 31 | B32: 45742 | C32: s/Drona/03/25/31 | D32: 45743 | E32: ganganagar vehicles pvt ltd | F32: 0-100Km | G32: Karnal | H32: HR38AC0263 | I32: 1109 | J32: Fixed | K32: 31 | L32: 210L Barrels | M32: =IFERROR(VLOOKUP(L32,'Material Master'!B:C,2,0),"") -> 210 | N32: 30 | O32: =IFERROR(M32*N32,"") -> 6300 | P32: Yes | R32: 45717 | U32: 180 | V32: 31 | W32: =IFERROR(U32*V32,"0") -> 5580 | Y32: =IFERROR((O32/1000)*Masters!$C$3,"0") -> 598.5 | AA32: =IFERROR(VLOOKUP(L32,Masters!G:H,2,0),"0") -> 30 | AB32: =IFERROR(AA32*N32,"0") -> 900 | AE32: =W32+Y32+AB32+AD32 -> 7078.5 | AG32: =M32&"-"&F32 -> 210-0-100Km | AH32: =IFERROR(VLOOKUP(AG32,Masters!N:O,2,0),"0") -> 220.5 | AI32: =AH32*N32 -> 6615 | AK32: =AI32-AE32 -> -463.5 | AN32: =IFERROR(U32/2,"0") -> 90
A33: =A32+1 -> 32 | B33: 45742 | C33: s/Drona/03/25/32 | D33: 45743 | E33: sumit auto store | F33: 0-100Km | G33: rohtak | H33: HR38AC7854 | I33: 1109 | J33: Fixed | K33: 29 | L33: 20L Buckets | M33: =IFERROR(VLOOKUP(L33,'Material Master'!B:C,2,0),"") -> 20 | N33: 300 | O33: =IFERROR(M33*N33,"") -> 6000 | P33: Yes | R33: 45717 | U33: 179 | V33: 31 | W33: =IFERROR(U33*V33,"0") -> 5549 | Y33: =IFERROR((O33/1000)*Masters!$C$3,"0") -> 570 | AA33: =IFERROR(VLOOKUP(L33,Masters!G:H,2,0),"0") -> 5 | AB33: =IFERROR(AA33*N33,"0") -> 1500 | AE33: =W33+Y33+AB33+AD33 -> 7619 | AG33: =M33&"-"&F33 -> 20-0-100Km | AH33: =IFERROR(VLOOKUP(AG33,Masters!N:O,2,0),"0") -> 21 | AI33: =AH33*N33 -> 6300 | AK33: =AI33-AE33 -> -1319 | AN33: =IFERROR(U33/2,"0") -> 89.5
A34: =A33+1 -> 33 | B34: 45742 | C34: s/Drona/03/25/33 | D34: 45743 | E34: raju motor store | F34: 0-100Km | G34: sonipat | H34: HR38AC0599 | I34: 1109 | J34: Fixed | K34: 30 | L34: 20L Buckets | M34: =IFERROR(VLOOKUP(L34,'Material Master'!B:C,2,0),"") -> 20 | N34: 300 | O34: =IFERROR(M34*N34,"") -> 6000 | P34: Yes | R34: 45717 | U34: 36 | V34: 31 | W34: =IFERROR(U34*V34,"0") -> 1116 | Y34: =IFERROR((O34/1000)*Masters!$C$3,"0") -> 570 | AA34: =IFERROR(VLOOKUP(L34,Masters!G:H,2,0),"0") -> 5 | AB34: =IFERROR(AA34*N34,"0") -> 1500 | AE34: =W34+Y34+AB34+AD34 -> 3186 | AG34: =M34&"-"&F34 -> 20-0-100Km | AH34: =IFERROR(VLOOKUP(AG34,Masters!N:O,2,0),"0") -> 21 | AI34: =AH34*N34 -> 6300 | AK34: =AI34-AE34 -> 3114 | AN34: =IFERROR(U34/2,"0") -> 18
A35: =A34+1 -> 34 | B35: 45743 | C35: s/Drona/03/25/34 | D35: 45756 | E35: hloc auto parts pvt.ltd. | F35: 0-100km | G35: delhi | H35: HR38AC0263 | I35: 1109 | J35: Fixed | K35: 75 | L35: 20L Buckets | M35: =IFERROR(VLOOKUP(L35,'Material Master'!B:C,2,0),"") -> 20 | N35: 300 | O35: =IFERROR(M35*N35,"") -> 6000 | P35: Yes | R35: 45717 | U35: 74 | V35: 31 | W35: =IFERROR(U35*V35,"0") -> 2294 | Y35: =IFERROR((O35/1000)*Masters!$C$3,"0") -> 570 | AA35: =IFERROR(VLOOKUP(L35,Masters!G:H,2,0),"0") -> 5 | AB35: =IFERROR(AA35*N35,"0") -> 1500 | AE35: =W35+Y35+AB35+AD35 -> 4364 | AG35: =M35&"-"&F35 -> 20-0-100km | AH35: =IFERROR(VLOOKUP(AG35,Masters!N:O,2,0),"0") -> 21 | AI35: =AH35*N35 -> 6300 | AK35: =AI35-AE35 -> 1936 | AN35: =IFERROR(U35/2,"0") -> 37
A36: =A35+1 -> 35 | B36: 45743 | C36: s/Drona/03/25/35 | D36: 45757 | E36: hloc auto parts pvt.ltd. | F36: 0-100km | G36: delhi | H36: HR38AC7854 | I36: 1109 | J36: Fixed | K36: 78 | L36: 20L Buckets | M36: =IFERROR(VLOOKUP(L36,'Material Master'!B:C,2,0),"") -> 20 | N36: 300 | O36: =IFERROR(M36*N36,"") -> 6000 | P36: Yes | R36: 45717 | U36: 75 | V36: 31 | W36: =IFERROR(U36*V36,"0") -> 2325 | Y36: =IFERROR((O36/1000)*Masters!$C$3,"0") -> 570 | AA36: =IFERROR(VLOOKUP(L36,Masters!G:H,2,0),"0") -> 5 | AB36: =IFERROR(AA36*N36,"0") -> 1500 | AE36: =W36+Y36+AB36+AD36 -> 4395 | AG36: =M36&"-"&F36 -> 20-0-100km | AH36: =IFERROR(VLOOKUP(AG36,Masters!N:O,2,0),"0") -> 21 | AI36: =AH36*N36 -> 6300 | AK36: =AI36-AE36 -> 1905 | AN36: =IFERROR(U36/2,"0") -> 37.5
A37: =A36+1 -> 36 | B37: 45743 | C37: s/Drona/03/25/36 | D37: 45762 | E37: hloc auto parts pvt.ltd. | F37: 0-100km | G37: delhi | H37: hR38AC7243 | I37: 1109 | J37: Fixed | K37: 88 | L37: 20L Buckets | M37: =IFERROR(VLOOKUP(L37,'Material Master'!B:C,2,0),"") -> 20 | N37: 300 | O37: =IFERROR(M37*N37,"") -> 6000 | P37: Yes | R37: 45717 | U37: 74 | V37: 31 | W37: =IFERROR(U37*V37,"0") -> 2294 | Y37: =IFERROR((O37/1000)*Masters!$C$3,"0") -> 570 | AA37: =IFERROR(VLOOKUP(L37,Masters!G:H,2,0),"0") -> 5 | AB37: =IFERROR(AA37*N37,"0") -> 1500 | AE37: =W37+Y37+AB37+AD37 -> 4364 | AG37: =M37&"-"&F37 -> 20-0-100km | AH37: =IFERROR(VLOOKUP(AG37,Masters!N:O,2,0),"0") -> 21 | AI37: =AH37*N37 -> 6300 | AK37: =AI37-AE37 -> 1936 | AN37: =IFERROR(U37/2,"0") -> 37
A38: =A37+1 -> 37 | B38: 45743 | C38: s/Drona/03/25/37 | D38: 45766 | E38: hloc auto parts pvt.ltd. | F38: 0-100km | G38: delhi | H38: hR38AC7854 | I38: 1109 | J38: Fixed | K38: 100 | L38: 20L Buckets | M38: =IFERROR(VLOOKUP(L38,'Material Master'!B:C,2,0),"") -> 20 | N38: 300 | O38: =IFERROR(M38*N38,"") -> 6000 | P38: Yes | R38: 45717 | U38: 67 | V38: 31 | W38: =IFERROR(U38*V38,"0") -> 2077 | Y38: =IFERROR((O38/1000)*Masters!$C$3,"0") -> 570 | AA38: =IFERROR(VLOOKUP(L38,Masters!G:H,2,0),"0") -> 5 | AB38: =IFERROR(AA38*N38,"0") -> 1500 | AE38: =W38+Y38+AB38+AD38 -> 4147 | AG38: =M38&"-"&F38 -> 20-0-100km | AH38: =IFERROR(VLOOKUP(AG38,Masters!N:O,2,0),"0") -> 21 | AI38: =AH38*N38 -> 6300 | AK38: =AI38-AE38 -> 2153 | AN38: =IFERROR(U38/2,"0") -> 33.5
A39: =A38+1 -> 38 | B39: 45743 | C39: s/Drona/03/25/38 | D39: 45769 | E39: hloc auto parts pvt.ltd. | F39: 0-100km | G39: delhi | H39: hR38AC0263 | I39: 1109 | J39: Fixed | K39: 105 | L39: 20L Buckets | M39: =IFERROR(VLOOKUP(L39,'Material Master'!B:C,2,0),"") -> 20 | N39: 300 | O39: =IFERROR(M39*N39,"") -> 6000 | P39: Yes | R39: 45717 | U39: 90 | V39: 31 | W39: =IFERROR(U39*V39,"0") -> 2790 | Y39: =IFERROR((O39/1000)*Masters!$C$3,"0") -> 570 | AA39: =IFERROR(VLOOKUP(L39,Masters!G:H,2,0),"0") -> 5 | AB39: =IFERROR(AA39*N39,"0") -> 1500 | AE39: =W39+Y39+AB39+AD39 -> 4860 | AG39: =M39&"-"&F39 -> 20-0-100km | AH39: =IFERROR(VLOOKUP(AG39,Masters!N:O,2,0),"0") -> 21 | AI39: =AH39*N39 -> 6300 | AK39: =AI39-AE39 -> 1440 | AN39: =IFERROR(U39/2,"0") -> 45
A40: =A39+1 -> 39 | B40: 45744 | C40: s/Drona/03/25/39 | D40: 45744 | E40: ashoka motors | F40: 101-250Km | G40: Hisar | H40: HR38AC0599 | I40: 1109 | J40: Fixed | K40: 35 | L40: 20L Buckets | M40: =IFERROR(VLOOKUP(L40,'Material Master'!B:C,2,0),"") -> 20 | N40: 300 | O40: =IFERROR(M40*N40,"") -> 6000 | P40: Yes | R40: 45717 | U40: 372 | V40: 31 | W40: =IFERROR(U40*V40,"0") -> 11532 | Y40: =IFERROR((O40/1000)*Masters!$C$3,"0") -> 570 | AA40: =IFERROR(VLOOKUP(L40,Masters!G:H,2,0),"0") -> 5 | AB40: =IFERROR(AA40*N40,"0") -> 1500 | AE40: =W40+Y40+AB40+AD40 -> 13602 | AG40: =M40&"-"&F40 -> 20-101-250Km | AH40: =IFERROR(VLOOKUP(AG40,Masters!N:O,2,0),"0") -> 40 | AI40: =AH40*N40 -> 12000 | AK40: =AI40-AE40 -> -1602 | AN40: =IFERROR(U40/2,"0") -> 186
A41: =A40+1 -> 40 | B41: 45744 | C41: s/Drona/03/25/40 | D41: 45744 | E41: pcj motors | F41: 101-250Km | G41: muzaffarnagar | H41: HR38X6465 | I41: 709 | J41: Fixed | K41: 33 | L41: 20L Buckets | M41: =IFERROR(VLOOKUP(L41,'Material Master'!B:C,2,0),"") -> 20 | N41: 100 | O41: =IFERROR(M41*N41,"") -> 2000 | P41: Yes | R41: 45717 | U41: 280 | V41: 31 | W41: =IFERROR(U41*V41,"0") -> 8680 | Y41: =IFERROR((O41/1000)*Masters!$C$3,"0") -> 190 | AA41: =IFERROR(VLOOKUP(L41,Masters!G:H,2,0),"0") -> 5 | AB41: =IFERROR(AA41*N41,"0") -> 500 | AE41: =W41+Y41+AB41+AD41 -> 9370 | AG41: =M41&"-"&F41 -> 20-101-250Km | AH41: =IFERROR(VLOOKUP(AG41,Masters!N:O,2,0),"0") -> 40 | AI41: =AH41*N41 -> 4000 | AK41: =AI41-AE41 -> -5370 | AN41: =IFERROR(U41/2,"0") -> 140
A42: =A41+1 -> 41 | B42: 45744 | C42: s/Drona/03/25/41 | D42: 45744 | E42: Sahni Motors | F42: 0-100Km | G42: Karnal | H42: HR38AC7243 | I42: 1109 | J42: Fixed | K42: 34 | L42: 20L Buckets | M42: =IFERROR(VLOOKUP(L42,'Material Master'!B:C,2,0),"") -> 20 | N42: 300 | O42: =IFERROR(M42*N42,"") -> 6000 | P42: Yes | R42: 45717 | U42: 179 | V42: 31 | W42: =IFERROR(U42*V42,"0") -> 5549 | Y42: =IFERROR((O42/1000)*Masters!$C$3,"0") -> 570 | AA42: =IFERROR(VLOOKUP(L42,Masters!G:H,2,0),"0") -> 5 | AB42: =IFERROR(AA42*N42,"0") -> 1500 | AE42: =W42+Y42+AB42+AD42 -> 7619 | AG42: =M42&"-"&F42 -> 20-0-100Km | AH42: =IFERROR(VLOOKUP(AG42,Masters!N:O,2,0),"0") -> 21 | AI42: =AH42*N42 -> 6300 | AK42: =AI42-AE42 -> -1319 | AN42: =IFERROR(U42/2,"0") -> 89.5
A43: =A42+1 -> 42 | B43: 45744 | C43: s/Drona/03/25/42 | D43: 45744 | E43: laxmi agencies | F43: 0-100Km | G43: pilkhuwa | H43: HR38AC7854 | I43: 909 | J43: Fixed | K43: 32 | L43: 20L Buckets | M43: =IFERROR(VLOOKUP(L43,'Material Master'!B:C,2,0),"") -> 20 | N43: 200 | O43: =IFERROR(M43*N43,"") -> 4000 | P43: Yes | R43: 45717 | U43: 175 | V43: 31 | W43: =IFERROR(U43*V43,"0") -> 5425 | Y43: =IFERROR((O43/1000)*Masters!$C$3,"0") -> 380 | AA43: =IFERROR(VLOOKUP(L43,Masters!G:H,2,0),"0") -> 5 | AB43: =IFERROR(AA43*N43,"0") -> 1000 | AE43: =W43+Y43+AB43+AD43 -> 6805 | AG43: =M43&"-"&F43 -> 20-0-100Km | AH43: =IFERROR(VLOOKUP(AG43,Masters!N:O,2,0),"0") -> 21 | AI43: =AH43*N43 -> 4200 | AK43: =AI43-AE43 -> -2605 | AN43: =IFERROR(U43/2,"0") -> 87.5
...

Sheet Market Vehicle Data
A1: Date | B1: Vehicle No. | C1: Pickup Point | D1: Destination | E1: Driver Name | F1: Driver No. | G1: Fare
A2: 45742 | B2: HR69D3754 | C2: Sonipat | D2: Rewari | E2: SUERESH | F2: 9991915392 | G2: 4500
A3: 45742 | B3: HR39F5155 | C3: Sonipat | D3: Hisar | E3: AMIT | F3: 8930099027 | G3: 8500
A4: 45748 | B4: RJ32GB5198 | C4: Sonipat | D4: Shahpura | E4: SATPAL | F4: 9664161140 | G4: 15000
A5: 45748 | B5: RJ14GK8841 | C5: Sonipat | D5: Shahpura | E5: RAMBIR | F5: 7823062311 | G5: 15000
A6: 45750 | B6: Gj02xx9199 | C6: Sonipat | D6: Shahpura | E6: SONU | F6: 9358156970 | G6: 15000
A7: 45751 | B7: RJ14GQ2021 | C7: Sonipat | D7: Shahpura | E7: vikas | F7: 9991467044 | G7: 15000
A8: 45751 | B8: RJ32GC7626 | C8: Sonipat | D8: Shahpura | E8: anil | F8: 7568761465 | G8: 15000
A9: 45813 | B9: GJ02ZZ7600 | C9: Sonipat | D9: rewari | E9: sonu | F9: 9992503467 | G9: 13000
A10: 45822 | B10: RJ32GC3170 | C10: Sonipat | D10: Rewari | E10: anil | F10: 9812354689 | G10: 13000
A11: 45829 | B11: UP93AT8450 | C11: Sonipat | D11: Rewari | E11: SANJAY | F11: 9728516610 | G11: 13000
A12: 45855 | B12: HR69F2786 | C12: Sonipat | D12: Dharuhera | E12: amit | F12: 8528615343 | G12: 12000
A13: 45865 | B13: HR69F2786 | C13: Sonipat | D13: Dharuhera | E13: amit | F13: 8528615343 | G13: 12500
... A20: 45903 | B20: HR69D2623 | C20: Sonipat | D20: moradabad | E20: aslam | F20: 7015595178 | G20: 10000
A21: 45928 | B21: HR69F2786 | C21: Sonipat | D21: Dharuhera | E21: sahid | F21: 7015595178
A22: 45930 | B22: HR69F2786 | C22: Sonipat | D22: Dharuhera | E22: sahid | F22: 7015595178
A23: 45930 | B23: RJ02GC6043 | C23: Sonipat | D23: alwar | E23: nahim | F23: 9887891170
A24: 45936 | B24: RJ02GC6247 | C24: Sonipat | D24: alwar | E24: VIKAS | F24: 9812445367
A25: 45936 | B25: RJ02GC5261 | C25: Sonipat | D25: alwar | E25: SAHID | F25: 7014547833
A26: 45937 | B26: RJ02GB4919 | C26: Sonipat | D26: alwar | E26: JAHID | F26: 8053436689
A27: 45937 | B27: RJ02GC4928 | C27: Sonipat | D27: alwar | E27: VIKAS | F27: 7015544377
A28: 45938 | B28: RJ02GC4969 | C28: Sonipat | D28: alwar | E28: SUNIL | F28: 9991642276
A29: 45938 | B29: HR55AJ2829 | C29: Sonipat | D29: alwar | E29: NAHIM | F29: 7850091362
A30: 45938 | B30: RJ02GC5375 | C30: Sonipat | D30: alwar | E30: ARJUN | F30: 9812543300
A31: 45939 | B31: RJ02GC4847 | C31: Sonipat | D31: alwar | E31: RAMBIR | F31: 8053437891

Sheet Vehicle Readings
A1: Out Date | B1: In Date | C1: Vehicle No. | D1: Driver Name | E1: Out Reading | F1: In Reading | G1: Running | I1: Cost
A2: 45734 | B2: 45735 | C2: HR38AC7243 | D2: Saleem | E2: 91386 | F2: 91575 | G2: =IF((F2-E2)<0,0,(F2-E2)) -> 189 | I2: =IFERROR(SUMPRODUCT($G2*VLOOKUP($C2,'Vehicle Master'!$D:$F,3,0)),"") -> 5859
A3: 45734 | B3: 45735 | C3: HR38AC0263 | D3: Saikul | E3: 66666 | F3: 66805 | G3: =IF((F3-E3)<0,0,(F3-E3)) -> 139 | I3: =IFERROR(SUMPRODUCT($G3*VLOOKUP($C3,'Vehicle Master'!$D:$F,3,0)),"") -> 4309
A4: 45734 | B4: 45736 | C4: HR38AC0599 | D4: Akram | E4: 100949 | F4: 101270 | G4: =IF((F4-E4)<0,0,(F4-E4)) -> 321 | I4: =IFERROR(SUMPRODUCT($G4*VLOOKUP($C4,'Vehicle Master'!$D:$F,3,0)),"") -> 9951
A5: 45734 | B5: 45735 | C5: HR38AC7854 | D5: Jahid | E5: 88855 | F5: 88928 | G5: =IF((F5-E5)<0,0,(F5-E5)) -> 73 | I5: =IFERROR(SUMPRODUCT($G5*VLOOKUP($C5,'Vehicle Master'!$D:$F,3,0)),"") -> 2263
A6: 45735 | B6: 45736 | C6: HR38AC7854 | D6: Jahid | E6: 88928 | F6: 89111 | G6: =IF((F6-E6)<0,0,(F6-E6)) -> 183 | I6: =IFERROR(SUMPRODUCT($G6*VLOOKUP($C6,'Vehicle Master'!$D:$F,3,0)),"") -> 5673
A7: 45735 | B7: 45737 | C7: HR38AC0263 | D7: Saikul | E7: 66805 | F7: 67177 | G7: =IF((F7-E7)<0,0,(F7-E7)) -> 372 | I7: =IFERROR(SUMPRODUCT($G7*VLOOKUP($C7,'Vehicle Master'!$D:$F,3,0)),"") -> 11532
A8: 45735 | B8: 45736 | C8: HR38AC7243 | D8: Saleem | E8: 91575 | F8: 91741 | G8: =IF((F8-E8)<0,0,(F8-E8)) -> 166 | I8: =IFERROR(SUMPRODUCT($G8*VLOOKUP($C8,'Vehicle Master'!$D:$F,3,0)),"") -> 5146
A9: 45736 | B9: 45737 | C9: HR38AC0599 | D9: Yakil | E9: 101270 | F9: 101513 | G9: =IF((F9-E9)<0,0,(F9-E9)) -> 243 | I9: =IFERROR(SUMPRODUCT($G9*VLOOKUP($C9,'Vehicle Master'!$D:$F,3,0)),"") -> 7533
A10: 45736 | B10: 45737 | C10: HR38AC7243 | D10: Saleem | E10: 91741 | F10: 91887 | G10: =IF((F10-E10)<0,0,(F10-E10)) -> 146 | I10: =IFERROR(SUMPRODUCT($G10*VLOOKUP($C10,'Vehicle Master'!$D:$F,3,0)),"") -> 4526
A11: 45736 | B11: 45737 | C11: HR38AC7854 | D11: Jahid | E11: 89111 | F11: 89288 | G11: =IF((F11-E11)<0,0,(F11-E11)) -> 177 | I11: =IFERROR(SUMPRODUCT($G11*VLOOKUP($C11,'Vehicle Master'!$D:$F,3,0)),"") -> 5487
A12: 45737 | B12: 45738 | C12: HR38AC0263 | D12: Saikul | E12: 67177 | F12: 67548 | G12: =IF((F12-E12)<0,0,(F12-E12)) -> 371 | I12: =IFERROR(SUMPRODUCT($G12*VLOOKUP($C12,'Vehicle Master'!$D:$F,3,0)),"") -> 11501
A13: 45737 | B13: 45738 | C13: HR38AC0599 | D13: Yakil | E13: 101513 | F13: 101645 | G13: =IF((F13-E13)<0,0,(F13-E13)) -> 132 | I13: =IFERROR(SUMPRODUCT($G13*VLOOKUP($C13,'Vehicle Master'!$D:$F,3,0)),"") -> 4092
... A20: 45740 | B20: 45743 | C20: HR38AC0599 | D20: Yakil | E20: 101816 | F20: 102204 | G20: =IF((F20-E20)<0,0,(F20-E20)) -> 388 | I20: =IFERROR(SUMPRODUCT($G20*VLOOKUP($C20,'Vehicle Master'!$D:$F,3,0)),"") -> 12028
A21: 45741 | B21: 45742 | C21: HR38AC7854 | D21: Jahid | E21: 89813 | F21: 90037 | G21: 224 | I21: =IFERROR(SUMPRODUCT($G21*VLOOKUP($C21,'Vehicle Master'!$D:$F,3,0)),"") -> 6944
A22: 45741 | B22: 45742 | C22: HR38AC7243 | D22: Saleem | E22: 92248 | F22: 92391 | G22: 143 | I22: =IFERROR(SUMPRODUCT($G22*VLOOKUP($C22,'Vehicle Master'!$D:$F,3,0)),"") -> 4433
A23: 45741 | B23: 45742 | C23: HR38AC0263 | D23: Saikul | E23: 68068 | F23: 68208 | G23: 140 | I23: =IFERROR(SUMPRODUCT($G23*VLOOKUP($C23,'Vehicle Master'!$D:$F,3,0)),"") -> 4340
A24: 45742 | B24: 45743 | C24: HR38AC7243 | D24: Saleem | E24: 92391 | F24: 92563 | G24: 172 | I24: =IFERROR(SUMPRODUCT($G24*VLOOKUP($C24,'Vehicle Master'!$D:$F,3,0)),"") -> 5332
A25: 45742 | B25: 45743 | C25: HR38AC0263 | D25: Saikul | E25: 68208 | F25: 68387 | G25: 179 | I25: =IFERROR(SUMPRODUCT($G25*VLOOKUP($C25,'Vehicle Master'!$D:$F,3,0)),"") -> 5549
A26: 45742 | B26: 45743 | C26: HR38AC7854 | D26: Jahid | E26: 90037 | F26: 90160 | G26: 123 | I26: =IFERROR(SUMPRODUCT($G26*VLOOKUP($C26,'Vehicle Master'!$D:$F,3,0)),"") -> 3813
A27: 45743 | B27: 45743 | C27: HR38AC7854 | D27: Jahid | E27: 90161 | F27: 90340 | G27: 179 | I27: =IFERROR(SUMPRODUCT($G27*VLOOKUP($C27,'Vehicle Master'!$D:$F,3,0)),"") -> 5549
A28: 45743 | B28: 45743 | C28: HR38AC0599 | D28: Yakil | E28: 102204 | F28: 102240 | G28: 36 | I28: =IFERROR(SUMPRODUCT($G28*VLOOKUP($C28,'Vehicle Master'!$D:$F,3,0)),"") -> 1116
A29: 45743 | B29: 45744 | C29: HR38AC0263 | D29: Saikul | E29: 68387 | F29: 68567 | G29: 180 | I29: =IFERROR(SUMPRODUCT($G29*VLOOKUP($C29,'Vehicle Master'!$D:$F,3,0)),"") -> 5580
A30: 45744 | B30: 45745 | C30: HR38AC7854 | D30: Jahid | E30: 90340 | F30: 90515 | G30: 175 | I30: =IFERROR(SUMPRODUCT($G30*VLOOKUP($C30,'Vehicle Master'!$D:$F,3,0)),"") -> 5425
A31: 45744 | B31: 45746 | C31: HR38X6465 | D31: Saikul | E31: 282816 | F31: 283096 | G31: 280 | I31: =IFERROR(SUMPRODUCT($G31*VLOOKUP($C31,'Vehicle Master'!$D:$F,3,0)),"") -> 8400
A32: 45744 | B32: 45745 | C32: HR38AC7243 | D32: Saleem | E32: 92563 | F32: 92742 | G32: 179 | I32: =IFERROR(SUMPRODUCT($G32*VLOOKUP($C32,'Vehicle Master'!$D:$F,3,0)),"") -> 5549
... A36: 45745 | B36: 45746 | C36: HR38AC7854 | D36: Yakil | E36: 90515 | F36: 90696 | G36: 181 | I36: =IFERROR(SUMPRODUCT($G36*VLOOKUP($C36,'Vehicle Master'!$D:$F,3,0)),"") -> 5611
A37: 45745 | B37: 45746 | C37: HR38AC0599 | D37: Saleem | E37: 102636 | F37: 102770 | G37: =IF((F37-E37)<0,0,(F37-E37)) -> 134 | I37: =IFERROR(SUMPRODUCT($G37*VLOOKUP($C37,'Vehicle Master'!$D:$F,3,0)),"") -> 4154
A38: 45745 | B38: 45746 | C38: HR38AC7243 | D38: Jahid | E38: 92742 | F38: 93040 | G38: =IF((F38-E38)<0,0,(F38-E38)) -> 298 | I38: =IFERROR(SUMPRODUCT($G38*VLOOKUP($C38,'Vehicle Master'!$D:$F,3,0)),"") -> 9238
A39: 45746 | B39: 45747 | C39: HR38X6465 | D39: Saikul | E39: 283096 | F39: 283286 | G39: =IF((F39-E39)<0,0,(F39-E39)) -> 190 | I39: =IFERROR(SUMPRODUCT($G39*VLOOKUP($C39,'Vehicle Master'!$D:$F,3,0)),"") -> 5700
A40: 45746 | B40: 45747 | C40: HR38AC0263 | D40: Saleem | E40: 68819 | F40: 68970 | G40: =IF((F40-E40)<0,0,(F40-E40)) -> 151 | I40: =IFERROR(SUMPRODUCT($G40*VLOOKUP($C40,'Vehicle Master'!$D:$F,3,0)),"") -> 4681
A41: 45746 | B41: 45747 | C41: HR38AC0599 | D41: Jahid | E41: 102695 | F41: 102912 | G41: =IF((F41-E41)<0,0,(F41-E41)) -> 217 | I41: =IFERROR(SUMPRODUCT($G41*VLOOKUP($C41,'Vehicle Master'!$D:$F,3,0)),"") -> 6727
A42: 45746 | B42: 45747 | C42: HR38AC7854 | D42: Saleem | E42: 90696 | F42: 90808 | G42: =IF((F42-E42)<0,0,(F42-E42)) -> 112 | I42: =IFERROR(SUMPRODUCT($G42*VLOOKUP($C42,'Vehicle Master'!$D:$F,3,0)),"") -> 3472
A43: 45747 | B43: 45748 | C43: HR38X6465 | D43: Jahid | E43: 283286 | F43: 283533 | G43: =IF((F43-E43)<0,0,(F43-E43)) -> 247 | I43: =IFERROR(SUMPRODUCT($G43*VLOOKUP($C43,'Vehicle Master'!$D:$F,3,0)),"") -> 7410
A44: 45747 | B44: 45748 | C44: HR38AC0599 | D44: Saikul | E44: 102912 | F44: 103093 | G44: =IF((F44-E44)<0,0,(F44-E44)) -> 181 | I44: =IFERROR(SUMPRODUCT($G44*VLOOKUP($C44,'Vehicle Master'!$D:$F,3,0)),"") -> 5611
A45: 45747 | B45: 45748 | C45: HR38AC0263 | D45: Saleem | E45: 68970 | F45: 69144 | G45: =IF((F45-E45)<0,0,(F45-E45)) -> 174 | I45: =IFERROR(SUMPRODUCT($G45*VLOOKUP($C45,'Vehicle Master'!$D:$F,3,0)),"") -> 5394
A46: 45747 | B46: 45748 | C46: HR38AC7854 | D46: Jahid | E46: 90808 | F46: 90920 | G46: =IF((F46-E46)<0,0,(F46-E46)) -> 112 | I46: =IFERROR(SUMPRODUCT($G46*VLOOKUP($C46,'Vehicle Master'!$D:$F,3,0)),"") -> 3472
A47: 45748 | B47: 45749 | C47: HR38X6465 | D47: Saikul | E47: 283533 | F47: 284107 | G47: =IF((F47-E47)<0,0,(F47-E47)) -> 574 | I47: =IFERROR(SUMPRODUCT($G47*VLOOKUP($C47,'Vehicle Master'!$D:$F,3,0)),"") -> 17220
A48: 45748 | B48: 45749 | C48: HR38AC0263 | D48: Sarvesh | E48: 69144 | F48: 69320 | G48: =IF((F48-E48)<0,0,(F48-E48)) -> 176 | I48: =IFERROR(SUMPRODUCT($G48*VLOOKUP($C48,'Vehicle Master'!$D:$F,3,0)),"") -> 5456
... A146: 45785 | B146: 45786 | C146: HR38AC7243 | D146: Premsagar | E146: 99519 | F146: 99669 | G146: =IF((F146-E146)<0,0,(F146-E146)) -> 150 | I146: =IFERROR(SUMPRODUCT($G146*VLOOKUP($C146,'Vehicle Master'!$D:$F,3,0)),"") -> 4650
...

Sheet Vehicle Master
A1: S.No | B1: Vehicle Type | C1: Model | D1: Vehicle Number | E1: Total Running | F1: Total Cost (Rs./Kms) | G1: Monthly Rate
A2: 1 | B2: 1109 | C2: Fixed | D2: HR38AC0263 | E2: =SUMIF('Vehicle Readings'!C:C,'Vehicle Master'!D2,'Vehicle Readings'!G:G) -> 32204 | F2: =G2/5000 -> 31 | G2: 155000
A3: =A2+1 -> 2 | B3: 1109 | C3: Fixed | D3: HR38AC7854 | E3: =SUMIF('Vehicle Readings'!C:C,'Vehicle Master'!D3,'Vehicle Readings'!G:G) -> 32097 | F3: =G3/5000 -> 31 | G3: 155000
A4: =A3+1 -> 3 | B4: 1109 | C4: Fixed | D4: HR38AC0599 | E4: =SUMIF('Vehicle Readings'!C:C,'Vehicle Master'!D4,'Vehicle Readings'!G:G) -> 32495 | F4: =G4/5000 -> 31 | G4: 155000
A5: =A4+1 -> 4 | B5: 1109 | C5: Fixed | D5: HR38AC7243 | E5: =SUMIF('Vehicle Readings'!C:C,'Vehicle Master'!D5,'Vehicle Readings'!G:G) -> 29618 | F5: =G5/5000 -> 31 | G5: 155000
A6: 5 | B6: 709 | C6: Market | D6: HR69D3754
A7: 6 | B7: 1109 | C7: Market | D7: HR39F5155
A8: 7 | B8: 909 | C8: Fixed | D8: HR38X6465 | E8: =SUMIF('Vehicle Readings'!C:C,'Vehicle Master'!D8,'Vehicle Readings'!G:G) -> 1472 | F8: =G8/(5000/3) -> 30 | G8: 50000
A9: 8 | B9: 709 | C9: Fixed | D9: HR38X6465 | E9: =SUMIF('Vehicle Readings'!C:C,'Vehicle Master'!D9,'Vehicle Readings'!G:G) -> 1472 | F9: =G9/(5000/3) -> 30 | G9: 50000
A10: 9 | B10: 2515 | C10: market | D10: RJ32GB5198
A11: 10 | B11: 2515 | C11: market | D11: RJ14GK8841
A12: 11 | B12: 2515 | C12: Market | D12: Gj02xx9199
A13: 12 | B13: 2515 | C13: Market | D13: RJ14GQ2021
A14: 13 | B14: 2515 | C14: Market | D14: RJ32GC7626
A15: 14 | B15: 2515 | C15: Market | D15: GJ02ZZ7600
A16: 15 | B16: 2515 | C16: Market | D16: RJ32GC3170
A17: 16 | B17: 2515 | C17: Market | D17: UP93AT8450
A18: 17 | B18: 2515 | C18: Market | D18: HR69F2786
A19: 18 | B19: 2515 | C19: Market | D19: HR55AN6307
A20: 19 | B20: 1109 | C20: Market | D20: RJ02GC6249
A21: 20 | B21: 1109 | C21: Market | D21: HR55AK9163
... A34: 32 | B34: 2515 | C34: Market | D34: RJ02GC4847

Sheet Category & Range Wise Outward
D1: 0-100Km | G1: 101-250Km | J1: 251-400Km | M1: 401-600Km | P1: Total
A2: Date | B2: LR Count | C2: Load (Ton) | D2: {=TRANSPOSE('Material Master'!$B$2:$B$4)} -> 20L Buckets | E2: 20L Jerry Can | F2: 210L Barrels | G2: {=TRANSPOSE('Material Master'!$B$2:$B$4)} -> 20L Buckets | H2: 20L Jerry Can | I2: 210L Barrels | J2: {=TRANSPOSE('Material Master'!$B$2:$B$4)} -> 20L Buckets | K2: 20L Jerry Can | L2: 210L Barrels | M2: {=TRANSPOSE('Material Master'!$B$2:$B$4)} -> 20L Buckets | N2: 20L Jerry Can | O2: 210L Barrels | P2: {=TRANSPOSE('Material Master'!$B$2:$B$4)} -> 20L Buckets | Q2: 20L Jerry Can | R2: 210L Barrels
A3: 45734 | B3: {=IF(A3>TODAY(),"",COUNTA(_xlfn.UNIQUE(_xlfn._xlws.FILTER('OPs Data'!$K:$K,'OPs Data'!$D:$D='Category & Range Wise Outward'!A3))))} -> 4 | C3: =IF(A3>TODAY(),"",SUMIF('OPs Data'!$D:$D,'Category & Range Wise Outward'!$A3,'OPs Data'!O:O)/1000) -> 22.63 | D3: =IF(A3>TODAY(),"",SUMIFS('OPs Data'!$N:$N,'OPs Data'!$F:$F,'Category & Range Wise Outward'!D$1,'OPs Data'!$D:$D,'Category & Range Wise Outward'!$A3,'OPs Data'!$L:$L,'Category & Range Wise Outward'!D$2)) -> 800 | E3: =IF(A3>TODAY(),"",SUMIFS('OPs Data'!$N:$N,'OPs Data'!$F:$F,'Category & Range Wise Outward'!D$1,'OPs Data'!$D:$D,'Category & Range Wise Outward'!$A3,'OPs Data'!$L:$L,'Category & Range Wise Outward'!E$2)) -> 0 | F3: =IF(A3>TODAY(),"",SUMIFS('OPs Data'!$N:$N,'OPs Data'!$F:$F,'Category & Range Wise Outward'!D$1,'OPs Data'!$D:$D,'Category & Range Wise Outward'!$A3,'OPs Data'!$L:$L,'Category & Range Wise Outward'!F$2)) -> 3 | G3: =IF(E3>TODAY(),"",SUMIFS('OPs Data'!$N:$N,'OPs Data'!$F:$F,'Category & Range Wise Outward'!G$1,'OPs Data'!$D:$D,'Category & Range Wise Outward'!$A3,'OPs Data'!$L:$L,'Category & Range Wise Outward'!G$2)) -> 300 | H3: =IF(E3>TODAY(),"",SUMIFS('OPs Data'!$N:$N,'OPs Data'!$F:$F,'Category & Range Wise Outward'!G$1,'OPs Data'!$D:$D,'Category & Range Wise Outward'!$A3,'OPs Data'!$L:$L,'Category & Range Wise Outward'!H$2)) -> 0 | I3: =IF(E3>TODAY(),"",SUMIFS('OPs Data'!$N:$N,'OPs Data'!$F:$F,'Category & Range Wise Outward'!G$1,'OPs Data'!$D:$D,'Category & Range Wise Outward'!$A3,'OPs Data'!$L:$L,'Category & Range Wise Outward'!I$2)) -> 0 | J3: =IF(H3>TODAY(),"",SUMIFS('OPs Data'!$N:$N,'OPs Data'!$F:$F,'Category & Range Wise Outward'!J$1,'OPs Data'!$D:$D,'Category & Range Wise Outward'!$A3,'OPs Data'!$L:$L,'Category & Range Wise Outward'!J$2)) -> 0 | K3: =IF(H3>TODAY(),"",SUMIFS('OPs Data'!$N:$N,'OPs Data'!$F:$F,'Category & Range Wise Outward'!J$1,'OPs Data'!$D:$D,'Category & Range Wise Outward'!$A3,'OPs Data'!$L:$L,'Category & Range Wise Outward'!K$2)) -> 0 | L3: =IF(H3>TODAY(),"",SUMIFS('OPs Data'!$N:$N,'OPs Data'!$F:$F,'Category & Range Wise Outward'!J$1,'OPs Data'!$D:$D,'Category & Range Wise Outward'!$A3,'OPs Data'!$L:$L,'Category & Range Wise Outward'!L$2)) -> 0 | M3: =IF(K3>TODAY(),"",SUMIFS('OPs Data'!$N:$N,'OPs Data'!$F:$F,'Category & Range Wise Outward'!M$1,'OPs Data'!$D:$D,'Category & Range Wise Outward'!$A3,'OPs Data'!$L:$L,'Category & Range Wise Outward'!M$2)) -> 0 | N3: =IF(K3>TODAY(),"",SUMIFS('OPs Data'!$N:$N,'OPs Data'!$F:$F,'Category & Range Wise Outward'!M$1,'OPs Data'!$D:$D,'Category & Range Wise Outward'!$A3,'OPs Data'!$L:$L,'Category & Range Wise Outward'!N$2)) -> 0 | O3: =IF(K3>TODAY(),"",SUMIFS('OPs Data'!$N:$N,'OPs Data'!$F:$F,'Category & Range Wise Outward'!M$1,'OPs Data'!$D:$D,'Category & Range Wise Outward'!$A3,'OPs Data'!$L:$L,'Category & Range Wise Outward'!O$2)) -> 0 | P3: =IF($A3>TODAY(),"",SUM(D3,G3,J3,M3)) -> 1100 | Q3: =IF($A3>TODAY(),"",SUM(E3,H3,K3,N3)) -> 0 | R3: =IF($A3>TODAY(),"",SUM(F3,I3,L3,O3)) -> 3
A4: 45735 | B4: {=IF(A4>TODAY(),"",COUNTA(_xlfn.UNIQUE(_xlfn._xlws.FILTER('OPs Data'!$K:$K,'OPs Data'!$D:$D='Category & Range Wise Outward'!A4))))} -> 3 | C4: =IF(A4>TODAY(),"",SUMIF('OPs Data'!$D:$D,'Category & Range Wise Outward'!$A4,'OPs Data'!O:O)/1000) -> 18.6 | D4: =IF(A4>TODAY(),"",SUMIFS('OPs Data'!$N:$N,'OPs Data'!$F:$F,'Category & Range Wise Outward'!D$1,'OPs Data'!$D:$D,'Category & Range Wise Outward'!$A4,'OPs Data'!$L:$L,'Category & Range Wise Outward'!D$2)) -> 0 | E4: =IF(A4>TODAY(),"",SUMIFS('OPs Data'!$N:$N,'OPs Data'!$F:$F,'Category & Range Wise Outward'!D$1,'OPs Data'!$D:$D,'Category & Range Wise Outward'!$A4,'OPs Data'!$L:$L,'Category & Range Wise Outward'!E$2)) -> 0 | F4: =IF(A4>TODAY(),"",SUMIFS('OPs Data'!$N:$N,'OPs Data'!$F:$F,'Category & Range Wise Outward'!D$1,'OPs Data'!$D:$D,'Category & Range Wise Outward'!$A4,'OPs Data'!$L:$L,'Category & Range Wise Outward'!F$2)) -> 60 | G4: =IF(E4>TODAY(),"",SUMIFS('OPs Data'!$N:$N,'OPs Data'!$F:$F,'Category & Range Wise Outward'!G$1,'OPs Data'!$D:$D,'Category & Range Wise Outward'!$A4,'OPs Data'!$L:$L,'Category & Range Wise Outward'!G$2)) -> 300 | H4: =IF(E4>TODAY(),"",SUMIFS('OPs Data'!$N:$N,'OPs Data'!$F:$F,'Category & Range Wise Outward'!G$1,'OPs Data'!$D:$D,'Category & Range Wise Outward'!$A4,'OPs Data'!$L:$L,'Category & Range Wise Outward'!H$2)) -> 0 | I4: =IF(E4>TODAY(),"",SUMIFS('OPs Data'!$N:$N,'OPs Data'!$F:$F,'Category & Range Wise Outward'!G$1,'OPs Data'!$D:$D,'Category & Range Wise Outward'!$A4,'OPs Data'!$L:$L,'Category & Range Wise Outward'!I$2)) -> 0 | J4: =IF(H4>TODAY(),"",SUMIFS('OPs Data'!$N:$N,'OPs Data'!$F:$F,'Category & Range Wise Outward'!J$1,'OPs Data'!$D:$D,'Category & Range Wise Outward'!$A4,'OPs Data'!$L:$L,'Category & Range Wise Outward'!J$2)) -> 0 | K4: =IF(H4>TODAY(),"",SUMIFS('OPs Data'!$N:$N,'OPs Data'!$F:$F,'Category & Range Wise Outward'!J$1,'OPs Data'!$D:$D,'Category & Range Wise Outward'!$A4,'OPs Data'!$L:$L,'Category & Range Wise Outward'!K$2)) -> 0 | L4: =IF(H4>TODAY(),"",SUMIFS('OPs Data'!$N:$N,'OPs Data'!$F:$F,'Category & Range Wise Outward'!J$1,'OPs Data'!$D:$D,'Category & Range Wise Outward'!$A4,'OPs Data'!$L:$L,'Category & Range Wise Outward'!L$2)) -> 0 | M4: =IF(K4>TODAY(),"",SUMIFS('OPs Data'!$N:$N,'OPs Data'!$F:$F,'Category & Range Wise Outward'!M$1,'OPs Data'!$D:$D,'Category & Range Wise Outward'!$A4,'OPs Data'!$L:$L,'Category & Range Wise Outward'!M$2)) -> 0 | N4: =IF(K4>TODAY(),"",SUMIFS('OPs Data'!$N:$N,'OPs Data'!$F:$F,'Category & Range Wise Outward'!M$1,'OPs Data'!$D:$D,'Category & Range Wise Outward'!$A4,'OPs Data'!$L:$L,'Category & Range Wise Outward'!N$2)) -> 0 | O4: =IF(K4>TODAY(),"",SUMIFS('OPs Data'!$N:$N,'OPs Data'!$F:$F,'Category & Range Wise Outward'!M$1,'OPs Data'!$D:$D,'Category & Range Wise Outward'!$A4,'OPs Data'!$L:$L,'Category & Range Wise Outward'!O$2)) -> 0 | P4: =IF($A4>TODAY(),"",SUM(D4,G4,J4,M4)) -> 300 | Q4: =IF($A4>TODAY(),"",SUM(E4,H4,K4,N4)) -> 0 | R4: =IF($A4>TODAY(),"",SUM(F4,I4,L4,O4)) -> 60
A5: 45736 | B5: {=IF(A5>TODAY(),"",COUNTA(_xlfn.UNIQUE(_xlfn._xlws.FILTER('OPs Data'!$K:$K,'OPs Data'!$D:$D='Category & Range Wise Outward'!A5))))} -> 3 | C5: =IF(A5>TODAY(),"",SUMIF('OPs Data'!$D:$D,'Category & Range Wise Outward'!$A5,'OPs Data'!O:O)/1000) -> 10 | D5: =IF(A5>TODAY(),"",SUMIFS('OPs Data'!$N:$N,'OPs Data'!$F:$F,'Category & Range Wise Outward'!D$1,'OPs Data'!$D:$D,'Category & Range Wise Outward'!$A5,'OPs Data'!$L:$L,'Category & Range Wise Outward'!D$2)) -> 400 | E5: =IF(A5>TODAY(),"",SUMIFS('OPs Data'!$N:$N,'OPs Data'!$F:$F,'Category & Range Wise Outward'!D$1,'OPs Data'!$D:$D,'Category & Range Wise Outward'!$A5,'OPs Data'!$L:$L,'Category & Range Wise Outward'!E$2)) -> 0 | F5: =IF(A5>TODAY(),"",SUMIFS('OPs Data'!$N:$N,'OPs Data'!$F:$F,'Category & Range Wise Outward'!D$1,'OPs Data'!$D:$D,'Category & Range Wise Outward'!$A5,'OPs Data'!$L:$L,'Category & Range Wise Outward'!F$2)) -> 0 | G5: =IF(E5>TODAY(),"",SUMIFS('OPs Data'!$N:$N,'OPs Data'!$F:$F,'Category & Range Wise Outward'!G$1,'OPs Data'!$D:$D,'Category & Range Wise Outward'!$A5,'OPs Data'!$L:$L,'Category & Range Wise Outward'!G$2)) -> 100 | H5: =IF(E5>TODAY(),"",SUMIFS('OPs Data'!$N:$N,'OPs Data'!$F:$F,'Category & Range Wise Outward'!G$1,'OPs Data'!$D:$D,'Category & Range Wise Outward'!$A5,'OPs Data'!$L:$L,'Category & Range Wise Outward'!H$2)) -> 0 | I5: =IF(E5>TODAY(),"",SUMIFS('OPs Data'!$N:$N,'OPs Data'!$F:$F,'Category & Range Wise Outward'!G$1,'OPs Data'!$D:$D,'Category & Range Wise Outward'!$A5,'OPs Data'!$L:$L,'Category & Range Wise Outward'!I$2)) -> 0 | J5: =IF(H5>TODAY(),"",SUMIFS('OPs Data'!$N:$N,'OPs Data'!$F:$F,'Category & Range Wise Outward'!J$1,'OPs Data'!$D:$D,'Category & Range Wise Outward'!$A5,'OPs Data'!$L:$L,'Category & Range Wise Outward'!J$2)) -> 0 | K5: =IF(H5>TODAY(),"",SUMIFS('OPs Data'!$N:$N,'OPs Data'!$F:$F,'Category & Range Wise Outward'!J$1,'OPs Data'!$D:$D,'Category & Range Wise Outward'!$A5,'OPs Data'!$L:$L,'Category & Range Wise Outward'!K$2)) -> 0 | L5: =IF(H5>TODAY(),"",SUMIFS('OPs Data'!$N:$N,'OPs Data'!$F:$F,'Category & Range Wise Outward'!J$1,'OPs Data'!$D:$D,'Category & Range Wise Outward'!$A5,'OPs Data'!$L:$L,'Category & Range Wise Outward'!L$2)) -> 0 | M5: =IF(K5>TODAY(),"",SUMIFS('OPs Data'!$N:$N,'OPs Data'!$F:$F,'Category & Range Wise Outward'!M$1,'OPs Data'!$D:$D,'Category & Range Wise Outward'!$A5,'OPs Data'!$L:$L,'Category & Range Wise Outward'!M$2)) -> 0 | N5: =IF(K5>TODAY(),"",SUMIFS('OPs Data'!$N:$N,'OPs Data'!$F:$F,'Category & Range Wise Outward'!M$1,'OPs Data'!$D:$D,'Category & Range Wise Outward'!$A5,'OPs Data'!$L:$L,'Category & Range Wise Outward'!N$2)) -> 0 | O5: =IF(K5>TODAY(),"",SUMIFS('OPs Data'!$N:$N,'OPs Data'!$F:$F,'Category & Range Wise Outward'!M$1,'OPs Data'!$D:$D,'Category & Range Wise Outward'!$A5,'OPs Data'!$L:$L,'Category & Range Wise Outward'!O$2)) -> 0 | P5: =IF($A5>TODAY(),"",SUM(D5,G5,J5,M5)) -> 500 | Q5: =IF($A5>TODAY(),"",SUM(E5,H5,K5,N5)) -> 0 | R5: =IF($A5>TODAY(),"",SUM(F5,I5,L5,O5)) -> 0
A6: 45737 | B6: {=IF(A6>TODAY(),"",COUNTA(_xlfn.UNIQUE(_xlfn._xlws.FILTER('OPs Data'!$K:$K,'OPs Data'!$D:$D='Category & Range Wise Outward'!A6))))} -> 4 | C6: =IF(A6>TODAY(),"",SUMIF('OPs Data'!$D:$D,'Category & Range Wise Outward'!$A6,'OPs Data'!O:O)/1000) -> 24.3 | D6: =IF(A6>TODAY(),"",SUMIFS('OPs Data'!$N:$N,'OPs Data'!$F:$F,'Category & Range Wise Outward'!D$1,'OPs Data'!$D:$D,'Category & Range Wise Outward'!$A6,'OPs Data'!$L:$L,'Category & Range Wise Outward'!D$2)) -> 300 | E6: =IF(A6>TODAY(),"",SUMIFS('OPs Data'!$N:$N,'OPs Data'!$F:$F,'Category & Range Wise Outward'!D$1,'OPs Data'!$D:$D,'Category & Range Wise Outward'!$A6,'OPs Data'!$L:$L,'Category & Range Wise Outward'!E$2)) -> 0 | F6: =IF(A6>TODAY(),"",SUMIFS('OPs Data'!$N:$N,'OPs Data'!$F:$F,'Category & Range Wise Outward'!D$1,'OPs Data'!$D:$D,'Category & Range Wise Outward'!$A6,'OPs Data'!$L:$L,'Category & Range Wise Outward'!F$2)) -> 30 | G6: =IF(E6>TODAY(),"",SUMIFS('OPs Data'!$N:$N,'OPs Data'!$F:$F,'Category & Range Wise Outward'!G$1,'OPs Data'!$D:$D,'Category & Range Wise Outward'!$A6,'OPs Data'!$L:$L,'Category & Range Wise Outward'!G$2)) -> 300 | H6: =IF(E6>TODAY(),"",SUMIFS('OPs Data'!$N:$N,'OPs Data'!$F:$F,'Category & Range Wise Outward'!G$1,'OPs Data'!$D:$D,'Category & Range Wise Outward'!$A6,'OPs Data'!$L:$L,'Category & Range Wise Outward'!H$2)) -> 0 | I6: =IF(E6>TODAY(),"",SUMIFS('OPs Data'!$N:$N,'OPs Data'!$F:$F,'Category & Range Wise Outward'!G$1,'OPs Data'!$D:$D,'Category & Range Wise Outward'!$A6,'OPs Data'!$L:$L,'Category & Range Wise Outward'!I$2)) -> 0 | J6: =IF(H6>TODAY(),"",SUMIFS('OPs Data'!$N:$N,'OPs Data'!$F:$F,'Category & Range Wise Outward'!J$1,'OPs Data'!$D:$D,'Category & Range Wise Outward'!$A6,'OPs Data'!$L:$L,'Category & Range Wise Outward'!J$2)) -> 300 | K6: =IF(H6>TODAY(),"",SUMIFS('OPs Data'!$N:$N,'OPs Data'!$F:$F,'Category & Range Wise Outward'!J$1,'OPs Data'!$D:$D,'Category & Range Wise Outward'!$A6,'OPs Data'!$L:$L,'Category & Range Wise Outward'!K$2)) -> 0 | L6: =IF(H6>TODAY(),"",SUMIFS('OPs Data'!$N:$N,'OPs Data'!$F:$F,'Category & Range Wise Outward'!J$1,'OPs Data'!$D:$D,'Category & Range Wise Outward'!$A6,'OPs Data'!$L:$L,'Category & Range Wise Outward'!L$2)) -> 0 | M6: =IF(K6>TODAY(),"",SUMIFS('OPs Data'!$N:$N,'OPs Data'!$F:$F,'Category & Range Wise Outward'!M$1,'OPs Data'!$D:$D,'Category & Range Wise Outward'!$A6,'OPs Data'!$L:$L,'Category & Range Wise Outward'!M$2)) -> 0 | N6: =IF(K6>TODAY(),"",SUMIFS('OPs Data'!$N:$N,'OPs Data'!$F:$F,'Category & Range Wise Outward'!M$1,'OPs Data'!$D:$D,'Category & Range Wise Outward'!$A6,'OPs Data'!$L:$L,'Category & Range Wise Outward'!N$2)) -> 0 | O6: =IF(K6>TODAY(),"",SUMIFS('OPs Data'!$N:$N,'OPs Data'!$F:$F,'Category & Range Wise Outward'!M$1,'OPs Data'!$D:$D,'Category & Range Wise Outward'!$A6,'OPs Data'!$L:$L,'Category & Range Wise Outward'!O$2)) -> 0 | P6: =IF($A6>TODAY(),"",SUM(D6,G6,J6,M6)) -> 900 | Q6: =IF($A6>TODAY(),"",SUM(E6,H6,K6,N6)) -> 0 | R6: =IF($A6>TODAY(),"",SUM(F6,I6,L6,O6)) -> 30
